{
 "cells": [
  {
   "cell_type": "markdown",
   "metadata": {},
   "source": [
    "# Lab 11-1 MNIST_CNN"
   ]
  },
  {
   "cell_type": "code",
   "execution_count": 2,
   "metadata": {},
   "outputs": [
    {
     "name": "stderr",
     "output_type": "stream",
     "text": [
      "ERROR:root:Internal Python error in the inspect module.\n",
      "Below is the traceback from this internal error.\n",
      "\n",
      "ERROR:root:Internal Python error in the inspect module.\n",
      "Below is the traceback from this internal error.\n",
      "\n",
      "ERROR:root:Internal Python error in the inspect module.\n",
      "Below is the traceback from this internal error.\n",
      "\n"
     ]
    },
    {
     "name": "stdout",
     "output_type": "stream",
     "text": [
      "Traceback (most recent call last):\n",
      "  File \"/Users/mindongjun/opt/anaconda3/envs/test2/lib/python3.7/site-packages/IPython/core/interactiveshell.py\", line 3457, in run_code\n",
      "    exec(code_obj, self.user_global_ns, self.user_ns)\n",
      "  File \"/var/folders/fj/y92l0p5x6d9030lr98_z9d2r0000gn/T/ipykernel_30803/87607189.py\", line 6, in <module>\n",
      "    from tensorflow.examples.tutorials.mnist import input_data\n",
      "  File \"/Users/mindongjun/opt/anaconda3/envs/test2/lib/python3.7/site-packages/tensorflow_core/examples/tutorials/mnist/__init__.py\", line 21, in <module>\n",
      "    from tensorflow.examples.tutorials.mnist import input_data\n",
      "  File \"/Users/mindongjun/opt/anaconda3/envs/test2/lib/python3.7/site-packages/tensorflow_core/examples/tutorials/mnist/input_data.py\", line 30, in <module>\n",
      "    from tensorflow.contrib.learn.python.learn.datasets.mnist import read_data_sets\n",
      "  File \"/Users/mindongjun/opt/anaconda3/envs/test2/lib/python3.7/site-packages/tensorflow/__init__.py\", line 50, in __getattr__\n",
      "    module = self._load()\n",
      "  File \"/Users/mindongjun/opt/anaconda3/envs/test2/lib/python3.7/site-packages/tensorflow/__init__.py\", line 44, in _load\n",
      "    module = _importlib.import_module(self.__name__)\n",
      "  File \"/Users/mindongjun/opt/anaconda3/envs/test2/lib/python3.7/importlib/__init__.py\", line 127, in import_module\n",
      "    return _bootstrap._gcd_import(name[level:], package, level)\n",
      "  File \"/Users/mindongjun/opt/anaconda3/envs/test2/lib/python3.7/site-packages/tensorflow_core/contrib/__init__.py\", line 39, in <module>\n",
      "    from tensorflow.contrib import compiler\n",
      "  File \"/Users/mindongjun/opt/anaconda3/envs/test2/lib/python3.7/site-packages/tensorflow_core/contrib/compiler/__init__.py\", line 21, in <module>\n",
      "    from tensorflow.contrib.compiler import jit\n",
      "  File \"/Users/mindongjun/opt/anaconda3/envs/test2/lib/python3.7/site-packages/tensorflow_core/contrib/compiler/__init__.py\", line 22, in <module>\n",
      "    from tensorflow.contrib.compiler import xla\n",
      "  File \"/Users/mindongjun/opt/anaconda3/envs/test2/lib/python3.7/site-packages/tensorflow_core/contrib/compiler/xla.py\", line 22, in <module>\n",
      "    from tensorflow.python.estimator import model_fn as model_fn_lib\n",
      "  File \"/Users/mindongjun/opt/anaconda3/envs/test2/lib/python3.7/site-packages/tensorflow_core/python/estimator/model_fn.py\", line 26, in <module>\n",
      "    from tensorflow_estimator.python.estimator import model_fn\n",
      "  File \"/Users/mindongjun/opt/anaconda3/envs/test2/lib/python3.7/site-packages/tensorflow_estimator/__init__.py\", line 10, in <module>\n",
      "    from tensorflow_estimator._api.v1 import estimator\n",
      "  File \"/Users/mindongjun/opt/anaconda3/envs/test2/lib/python3.7/site-packages/tensorflow_estimator/_api/v1/estimator/__init__.py\", line 10, in <module>\n",
      "    from tensorflow_estimator._api.v1.estimator import experimental\n",
      "  File \"/Users/mindongjun/opt/anaconda3/envs/test2/lib/python3.7/site-packages/tensorflow_estimator/_api/v1/estimator/experimental/__init__.py\", line 10, in <module>\n",
      "    from tensorflow_estimator.python.estimator.canned.dnn import dnn_logit_fn_builder\n",
      "  File \"/Users/mindongjun/opt/anaconda3/envs/test2/lib/python3.7/site-packages/tensorflow_estimator/python/estimator/canned/dnn.py\", line 27, in <module>\n",
      "    from tensorflow_estimator.python.estimator import estimator\n",
      "  File \"/Users/mindongjun/opt/anaconda3/envs/test2/lib/python3.7/site-packages/tensorflow_estimator/python/estimator/estimator.py\", line 36, in <module>\n",
      "    from tensorflow.python.profiler import trace\n",
      "ImportError: cannot import name 'trace' from 'tensorflow.python.profiler' (/Users/mindongjun/opt/anaconda3/envs/test2/lib/python3.7/site-packages/tensorflow_core/python/profiler/__init__.py)\n",
      "\n",
      "During handling of the above exception, another exception occurred:\n",
      "\n",
      "Traceback (most recent call last):\n",
      "  File \"/Users/mindongjun/opt/anaconda3/envs/test2/lib/python3.7/site-packages/IPython/core/interactiveshell.py\", line 2077, in showtraceback\n",
      "    stb = value._render_traceback_()\n",
      "AttributeError: 'ImportError' object has no attribute '_render_traceback_'\n",
      "\n",
      "During handling of the above exception, another exception occurred:\n",
      "\n",
      "Traceback (most recent call last):\n",
      "  File \"/Users/mindongjun/opt/anaconda3/envs/test2/lib/python3.7/site-packages/IPython/core/ultratb.py\", line 1101, in get_records\n",
      "    return _fixed_getinnerframes(etb, number_of_lines_of_context, tb_offset)\n",
      "  File \"/Users/mindongjun/opt/anaconda3/envs/test2/lib/python3.7/site-packages/IPython/core/ultratb.py\", line 248, in wrapped\n",
      "    return f(*args, **kwargs)\n",
      "  File \"/Users/mindongjun/opt/anaconda3/envs/test2/lib/python3.7/site-packages/IPython/core/ultratb.py\", line 281, in _fixed_getinnerframes\n",
      "    records = fix_frame_records_filenames(inspect.getinnerframes(etb, context))\n",
      "  File \"/Users/mindongjun/opt/anaconda3/envs/test2/lib/python3.7/inspect.py\", line 1495, in getinnerframes\n",
      "    frameinfo = (tb.tb_frame,) + getframeinfo(tb, context)\n",
      "  File \"/Users/mindongjun/opt/anaconda3/envs/test2/lib/python3.7/inspect.py\", line 1453, in getframeinfo\n",
      "    filename = getsourcefile(frame) or getfile(frame)\n",
      "  File \"/Users/mindongjun/opt/anaconda3/envs/test2/lib/python3.7/inspect.py\", line 696, in getsourcefile\n",
      "    if getattr(getmodule(object, filename), '__loader__', None) is not None:\n",
      "  File \"/Users/mindongjun/opt/anaconda3/envs/test2/lib/python3.7/inspect.py\", line 733, in getmodule\n",
      "    if ismodule(module) and hasattr(module, '__file__'):\n",
      "  File \"/Users/mindongjun/opt/anaconda3/envs/test2/lib/python3.7/site-packages/tensorflow/__init__.py\", line 50, in __getattr__\n",
      "    module = self._load()\n",
      "  File \"/Users/mindongjun/opt/anaconda3/envs/test2/lib/python3.7/site-packages/tensorflow/__init__.py\", line 44, in _load\n",
      "    module = _importlib.import_module(self.__name__)\n",
      "  File \"/Users/mindongjun/opt/anaconda3/envs/test2/lib/python3.7/importlib/__init__.py\", line 127, in import_module\n",
      "    return _bootstrap._gcd_import(name[level:], package, level)\n",
      "  File \"<frozen importlib._bootstrap>\", line 1006, in _gcd_import\n",
      "  File \"<frozen importlib._bootstrap>\", line 983, in _find_and_load\n",
      "  File \"<frozen importlib._bootstrap>\", line 965, in _find_and_load_unlocked\n",
      "ModuleNotFoundError: No module named 'tensorflow_core.estimator'\n",
      "Traceback (most recent call last):\n",
      "  File \"/Users/mindongjun/opt/anaconda3/envs/test2/lib/python3.7/site-packages/IPython/core/interactiveshell.py\", line 3457, in run_code\n",
      "    exec(code_obj, self.user_global_ns, self.user_ns)\n",
      "  File \"/var/folders/fj/y92l0p5x6d9030lr98_z9d2r0000gn/T/ipykernel_30803/87607189.py\", line 6, in <module>\n",
      "    from tensorflow.examples.tutorials.mnist import input_data\n",
      "  File \"/Users/mindongjun/opt/anaconda3/envs/test2/lib/python3.7/site-packages/tensorflow_core/examples/tutorials/mnist/__init__.py\", line 21, in <module>\n",
      "    from tensorflow.examples.tutorials.mnist import input_data\n",
      "  File \"/Users/mindongjun/opt/anaconda3/envs/test2/lib/python3.7/site-packages/tensorflow_core/examples/tutorials/mnist/input_data.py\", line 30, in <module>\n",
      "    from tensorflow.contrib.learn.python.learn.datasets.mnist import read_data_sets\n",
      "  File \"/Users/mindongjun/opt/anaconda3/envs/test2/lib/python3.7/site-packages/tensorflow/__init__.py\", line 50, in __getattr__\n",
      "    module = self._load()\n",
      "  File \"/Users/mindongjun/opt/anaconda3/envs/test2/lib/python3.7/site-packages/tensorflow/__init__.py\", line 44, in _load\n",
      "    module = _importlib.import_module(self.__name__)\n",
      "  File \"/Users/mindongjun/opt/anaconda3/envs/test2/lib/python3.7/importlib/__init__.py\", line 127, in import_module\n",
      "    return _bootstrap._gcd_import(name[level:], package, level)\n",
      "  File \"/Users/mindongjun/opt/anaconda3/envs/test2/lib/python3.7/site-packages/tensorflow_core/contrib/__init__.py\", line 39, in <module>\n",
      "    from tensorflow.contrib import compiler\n",
      "  File \"/Users/mindongjun/opt/anaconda3/envs/test2/lib/python3.7/site-packages/tensorflow_core/contrib/compiler/__init__.py\", line 21, in <module>\n",
      "    from tensorflow.contrib.compiler import jit\n",
      "  File \"/Users/mindongjun/opt/anaconda3/envs/test2/lib/python3.7/site-packages/tensorflow_core/contrib/compiler/__init__.py\", line 22, in <module>\n",
      "    from tensorflow.contrib.compiler import xla\n",
      "  File \"/Users/mindongjun/opt/anaconda3/envs/test2/lib/python3.7/site-packages/tensorflow_core/contrib/compiler/xla.py\", line 22, in <module>\n",
      "    from tensorflow.python.estimator import model_fn as model_fn_lib\n",
      "  File \"/Users/mindongjun/opt/anaconda3/envs/test2/lib/python3.7/site-packages/tensorflow_core/python/estimator/model_fn.py\", line 26, in <module>\n",
      "    from tensorflow_estimator.python.estimator import model_fn\n",
      "  File \"/Users/mindongjun/opt/anaconda3/envs/test2/lib/python3.7/site-packages/tensorflow_estimator/__init__.py\", line 10, in <module>\n",
      "    from tensorflow_estimator._api.v1 import estimator\n",
      "  File \"/Users/mindongjun/opt/anaconda3/envs/test2/lib/python3.7/site-packages/tensorflow_estimator/_api/v1/estimator/__init__.py\", line 10, in <module>\n",
      "    from tensorflow_estimator._api.v1.estimator import experimental\n",
      "  File \"/Users/mindongjun/opt/anaconda3/envs/test2/lib/python3.7/site-packages/tensorflow_estimator/_api/v1/estimator/experimental/__init__.py\", line 10, in <module>\n",
      "    from tensorflow_estimator.python.estimator.canned.dnn import dnn_logit_fn_builder\n",
      "  File \"/Users/mindongjun/opt/anaconda3/envs/test2/lib/python3.7/site-packages/tensorflow_estimator/python/estimator/canned/dnn.py\", line 27, in <module>\n",
      "    from tensorflow_estimator.python.estimator import estimator\n",
      "  File \"/Users/mindongjun/opt/anaconda3/envs/test2/lib/python3.7/site-packages/tensorflow_estimator/python/estimator/estimator.py\", line 36, in <module>\n",
      "    from tensorflow.python.profiler import trace\n",
      "ImportError: cannot import name 'trace' from 'tensorflow.python.profiler' (/Users/mindongjun/opt/anaconda3/envs/test2/lib/python3.7/site-packages/tensorflow_core/python/profiler/__init__.py)\n",
      "\n",
      "During handling of the above exception, another exception occurred:\n",
      "\n",
      "Traceback (most recent call last):\n",
      "  File \"/Users/mindongjun/opt/anaconda3/envs/test2/lib/python3.7/site-packages/IPython/core/interactiveshell.py\", line 2077, in showtraceback\n",
      "    stb = value._render_traceback_()\n",
      "AttributeError: 'ImportError' object has no attribute '_render_traceback_'\n",
      "\n",
      "During handling of the above exception, another exception occurred:\n",
      "\n",
      "Traceback (most recent call last):\n",
      "  File \"/Users/mindongjun/opt/anaconda3/envs/test2/lib/python3.7/site-packages/IPython/core/interactiveshell.py\", line 3377, in run_ast_nodes\n",
      "    if (await self.run_code(code, result,  async_=asy)):\n",
      "  File \"/Users/mindongjun/opt/anaconda3/envs/test2/lib/python3.7/site-packages/IPython/core/interactiveshell.py\", line 3474, in run_code\n",
      "    self.showtraceback(running_compiled_code=True)\n",
      "  File \"/Users/mindongjun/opt/anaconda3/envs/test2/lib/python3.7/site-packages/IPython/core/interactiveshell.py\", line 2080, in showtraceback\n",
      "    value, tb, tb_offset=tb_offset)\n",
      "  File \"/Users/mindongjun/opt/anaconda3/envs/test2/lib/python3.7/site-packages/IPython/core/ultratb.py\", line 1368, in structured_traceback\n",
      "    self, etype, value, tb, tb_offset, number_of_lines_of_context)\n",
      "  File \"/Users/mindongjun/opt/anaconda3/envs/test2/lib/python3.7/site-packages/IPython/core/ultratb.py\", line 1268, in structured_traceback\n",
      "    self, etype, value, tb, tb_offset, number_of_lines_of_context\n",
      "  File \"/Users/mindongjun/opt/anaconda3/envs/test2/lib/python3.7/site-packages/IPython/core/ultratb.py\", line 1125, in structured_traceback\n",
      "    tb_offset)\n",
      "  File \"/Users/mindongjun/opt/anaconda3/envs/test2/lib/python3.7/site-packages/IPython/core/ultratb.py\", line 1082, in format_exception_as_a_whole\n",
      "    last_unique, recursion_repeat = find_recursion(orig_etype, evalue, records)\n",
      "  File \"/Users/mindongjun/opt/anaconda3/envs/test2/lib/python3.7/site-packages/IPython/core/ultratb.py\", line 382, in find_recursion\n",
      "    return len(records), 0\n",
      "TypeError: object of type 'NoneType' has no len()\n",
      "\n",
      "During handling of the above exception, another exception occurred:\n",
      "\n",
      "Traceback (most recent call last):\n",
      "  File \"/Users/mindongjun/opt/anaconda3/envs/test2/lib/python3.7/site-packages/IPython/core/interactiveshell.py\", line 2077, in showtraceback\n",
      "    stb = value._render_traceback_()\n",
      "AttributeError: 'TypeError' object has no attribute '_render_traceback_'\n",
      "\n",
      "During handling of the above exception, another exception occurred:\n",
      "\n",
      "Traceback (most recent call last):\n",
      "  File \"/Users/mindongjun/opt/anaconda3/envs/test2/lib/python3.7/site-packages/IPython/core/ultratb.py\", line 1101, in get_records\n",
      "    return _fixed_getinnerframes(etb, number_of_lines_of_context, tb_offset)\n",
      "  File \"/Users/mindongjun/opt/anaconda3/envs/test2/lib/python3.7/site-packages/IPython/core/ultratb.py\", line 248, in wrapped\n",
      "    return f(*args, **kwargs)\n",
      "  File \"/Users/mindongjun/opt/anaconda3/envs/test2/lib/python3.7/site-packages/IPython/core/ultratb.py\", line 281, in _fixed_getinnerframes\n",
      "    records = fix_frame_records_filenames(inspect.getinnerframes(etb, context))\n",
      "  File \"/Users/mindongjun/opt/anaconda3/envs/test2/lib/python3.7/inspect.py\", line 1495, in getinnerframes\n",
      "    frameinfo = (tb.tb_frame,) + getframeinfo(tb, context)\n",
      "  File \"/Users/mindongjun/opt/anaconda3/envs/test2/lib/python3.7/inspect.py\", line 1453, in getframeinfo\n",
      "    filename = getsourcefile(frame) or getfile(frame)\n",
      "  File \"/Users/mindongjun/opt/anaconda3/envs/test2/lib/python3.7/inspect.py\", line 696, in getsourcefile\n",
      "    if getattr(getmodule(object, filename), '__loader__', None) is not None:\n",
      "  File \"/Users/mindongjun/opt/anaconda3/envs/test2/lib/python3.7/inspect.py\", line 733, in getmodule\n",
      "    if ismodule(module) and hasattr(module, '__file__'):\n",
      "  File \"/Users/mindongjun/opt/anaconda3/envs/test2/lib/python3.7/site-packages/tensorflow/__init__.py\", line 50, in __getattr__\n",
      "    module = self._load()\n",
      "  File \"/Users/mindongjun/opt/anaconda3/envs/test2/lib/python3.7/site-packages/tensorflow/__init__.py\", line 44, in _load\n",
      "    module = _importlib.import_module(self.__name__)\n",
      "  File \"/Users/mindongjun/opt/anaconda3/envs/test2/lib/python3.7/importlib/__init__.py\", line 127, in import_module\n",
      "    return _bootstrap._gcd_import(name[level:], package, level)\n",
      "  File \"<frozen importlib._bootstrap>\", line 1006, in _gcd_import\n",
      "  File \"<frozen importlib._bootstrap>\", line 983, in _find_and_load\n",
      "  File \"<frozen importlib._bootstrap>\", line 965, in _find_and_load_unlocked\n",
      "ModuleNotFoundError: No module named 'tensorflow_core.estimator'\n",
      "Traceback (most recent call last):\n",
      "  File \"/Users/mindongjun/opt/anaconda3/envs/test2/lib/python3.7/site-packages/IPython/core/interactiveshell.py\", line 3457, in run_code\n",
      "    exec(code_obj, self.user_global_ns, self.user_ns)\n",
      "  File \"/var/folders/fj/y92l0p5x6d9030lr98_z9d2r0000gn/T/ipykernel_30803/87607189.py\", line 6, in <module>\n",
      "    from tensorflow.examples.tutorials.mnist import input_data\n",
      "  File \"/Users/mindongjun/opt/anaconda3/envs/test2/lib/python3.7/site-packages/tensorflow_core/examples/tutorials/mnist/__init__.py\", line 21, in <module>\n",
      "    from tensorflow.examples.tutorials.mnist import input_data\n",
      "  File \"/Users/mindongjun/opt/anaconda3/envs/test2/lib/python3.7/site-packages/tensorflow_core/examples/tutorials/mnist/input_data.py\", line 30, in <module>\n",
      "    from tensorflow.contrib.learn.python.learn.datasets.mnist import read_data_sets\n",
      "  File \"/Users/mindongjun/opt/anaconda3/envs/test2/lib/python3.7/site-packages/tensorflow/__init__.py\", line 50, in __getattr__\n",
      "    module = self._load()\n",
      "  File \"/Users/mindongjun/opt/anaconda3/envs/test2/lib/python3.7/site-packages/tensorflow/__init__.py\", line 44, in _load\n",
      "    module = _importlib.import_module(self.__name__)\n",
      "  File \"/Users/mindongjun/opt/anaconda3/envs/test2/lib/python3.7/importlib/__init__.py\", line 127, in import_module\n",
      "    return _bootstrap._gcd_import(name[level:], package, level)\n",
      "  File \"/Users/mindongjun/opt/anaconda3/envs/test2/lib/python3.7/site-packages/tensorflow_core/contrib/__init__.py\", line 39, in <module>\n",
      "    from tensorflow.contrib import compiler\n",
      "  File \"/Users/mindongjun/opt/anaconda3/envs/test2/lib/python3.7/site-packages/tensorflow_core/contrib/compiler/__init__.py\", line 21, in <module>\n",
      "    from tensorflow.contrib.compiler import jit\n",
      "  File \"/Users/mindongjun/opt/anaconda3/envs/test2/lib/python3.7/site-packages/tensorflow_core/contrib/compiler/__init__.py\", line 22, in <module>\n",
      "    from tensorflow.contrib.compiler import xla\n",
      "  File \"/Users/mindongjun/opt/anaconda3/envs/test2/lib/python3.7/site-packages/tensorflow_core/contrib/compiler/xla.py\", line 22, in <module>\n",
      "    from tensorflow.python.estimator import model_fn as model_fn_lib\n",
      "  File \"/Users/mindongjun/opt/anaconda3/envs/test2/lib/python3.7/site-packages/tensorflow_core/python/estimator/model_fn.py\", line 26, in <module>\n",
      "    from tensorflow_estimator.python.estimator import model_fn\n",
      "  File \"/Users/mindongjun/opt/anaconda3/envs/test2/lib/python3.7/site-packages/tensorflow_estimator/__init__.py\", line 10, in <module>\n",
      "    from tensorflow_estimator._api.v1 import estimator\n",
      "  File \"/Users/mindongjun/opt/anaconda3/envs/test2/lib/python3.7/site-packages/tensorflow_estimator/_api/v1/estimator/__init__.py\", line 10, in <module>\n",
      "    from tensorflow_estimator._api.v1.estimator import experimental\n",
      "  File \"/Users/mindongjun/opt/anaconda3/envs/test2/lib/python3.7/site-packages/tensorflow_estimator/_api/v1/estimator/experimental/__init__.py\", line 10, in <module>\n",
      "    from tensorflow_estimator.python.estimator.canned.dnn import dnn_logit_fn_builder\n",
      "  File \"/Users/mindongjun/opt/anaconda3/envs/test2/lib/python3.7/site-packages/tensorflow_estimator/python/estimator/canned/dnn.py\", line 27, in <module>\n",
      "    from tensorflow_estimator.python.estimator import estimator\n",
      "  File \"/Users/mindongjun/opt/anaconda3/envs/test2/lib/python3.7/site-packages/tensorflow_estimator/python/estimator/estimator.py\", line 36, in <module>\n",
      "    from tensorflow.python.profiler import trace\n",
      "ImportError: cannot import name 'trace' from 'tensorflow.python.profiler' (/Users/mindongjun/opt/anaconda3/envs/test2/lib/python3.7/site-packages/tensorflow_core/python/profiler/__init__.py)\n",
      "\n",
      "During handling of the above exception, another exception occurred:\n",
      "\n",
      "Traceback (most recent call last):\n",
      "  File \"/Users/mindongjun/opt/anaconda3/envs/test2/lib/python3.7/site-packages/IPython/core/interactiveshell.py\", line 2077, in showtraceback\n",
      "    stb = value._render_traceback_()\n",
      "AttributeError: 'ImportError' object has no attribute '_render_traceback_'\n",
      "\n",
      "During handling of the above exception, another exception occurred:\n",
      "\n",
      "Traceback (most recent call last):\n",
      "  File \"/Users/mindongjun/opt/anaconda3/envs/test2/lib/python3.7/site-packages/IPython/core/interactiveshell.py\", line 3377, in run_ast_nodes\n",
      "    if (await self.run_code(code, result,  async_=asy)):\n",
      "  File \"/Users/mindongjun/opt/anaconda3/envs/test2/lib/python3.7/site-packages/IPython/core/interactiveshell.py\", line 3474, in run_code\n",
      "    self.showtraceback(running_compiled_code=True)\n",
      "  File \"/Users/mindongjun/opt/anaconda3/envs/test2/lib/python3.7/site-packages/IPython/core/interactiveshell.py\", line 2080, in showtraceback\n",
      "    value, tb, tb_offset=tb_offset)\n",
      "  File \"/Users/mindongjun/opt/anaconda3/envs/test2/lib/python3.7/site-packages/IPython/core/ultratb.py\", line 1368, in structured_traceback\n",
      "    self, etype, value, tb, tb_offset, number_of_lines_of_context)\n",
      "  File \"/Users/mindongjun/opt/anaconda3/envs/test2/lib/python3.7/site-packages/IPython/core/ultratb.py\", line 1268, in structured_traceback\n",
      "    self, etype, value, tb, tb_offset, number_of_lines_of_context\n",
      "  File \"/Users/mindongjun/opt/anaconda3/envs/test2/lib/python3.7/site-packages/IPython/core/ultratb.py\", line 1125, in structured_traceback\n",
      "    tb_offset)\n",
      "  File \"/Users/mindongjun/opt/anaconda3/envs/test2/lib/python3.7/site-packages/IPython/core/ultratb.py\", line 1082, in format_exception_as_a_whole\n",
      "    last_unique, recursion_repeat = find_recursion(orig_etype, evalue, records)\n",
      "  File \"/Users/mindongjun/opt/anaconda3/envs/test2/lib/python3.7/site-packages/IPython/core/ultratb.py\", line 382, in find_recursion\n",
      "    return len(records), 0\n",
      "TypeError: object of type 'NoneType' has no len()\n",
      "\n",
      "During handling of the above exception, another exception occurred:\n",
      "\n",
      "Traceback (most recent call last):\n",
      "  File \"/Users/mindongjun/opt/anaconda3/envs/test2/lib/python3.7/site-packages/IPython/core/interactiveshell.py\", line 2077, in showtraceback\n",
      "    stb = value._render_traceback_()\n",
      "AttributeError: 'TypeError' object has no attribute '_render_traceback_'\n",
      "\n",
      "During handling of the above exception, another exception occurred:\n",
      "\n",
      "Traceback (most recent call last):\n",
      "  File \"/Users/mindongjun/opt/anaconda3/envs/test2/lib/python3.7/site-packages/IPython/core/interactiveshell.py\", line 2960, in _run_cell\n",
      "    return runner(coro)\n",
      "  File \"/Users/mindongjun/opt/anaconda3/envs/test2/lib/python3.7/site-packages/IPython/core/async_helpers.py\", line 78, in _pseudo_sync_runner\n",
      "    coro.send(None)\n",
      "  File \"/Users/mindongjun/opt/anaconda3/envs/test2/lib/python3.7/site-packages/IPython/core/interactiveshell.py\", line 3186, in run_cell_async\n",
      "    interactivity=interactivity, compiler=compiler, result=result)\n",
      "  File \"/Users/mindongjun/opt/anaconda3/envs/test2/lib/python3.7/site-packages/IPython/core/interactiveshell.py\", line 3396, in run_ast_nodes\n",
      "    self.showtraceback()\n",
      "  File \"/Users/mindongjun/opt/anaconda3/envs/test2/lib/python3.7/site-packages/IPython/core/interactiveshell.py\", line 2080, in showtraceback\n",
      "    value, tb, tb_offset=tb_offset)\n",
      "  File \"/Users/mindongjun/opt/anaconda3/envs/test2/lib/python3.7/site-packages/IPython/core/ultratb.py\", line 1368, in structured_traceback\n",
      "    self, etype, value, tb, tb_offset, number_of_lines_of_context)\n",
      "  File \"/Users/mindongjun/opt/anaconda3/envs/test2/lib/python3.7/site-packages/IPython/core/ultratb.py\", line 1268, in structured_traceback\n",
      "    self, etype, value, tb, tb_offset, number_of_lines_of_context\n",
      "  File \"/Users/mindongjun/opt/anaconda3/envs/test2/lib/python3.7/site-packages/IPython/core/ultratb.py\", line 1143, in structured_traceback\n",
      "    chained_exceptions_tb_offset)\n",
      "  File \"/Users/mindongjun/opt/anaconda3/envs/test2/lib/python3.7/site-packages/IPython/core/ultratb.py\", line 1082, in format_exception_as_a_whole\n",
      "    last_unique, recursion_repeat = find_recursion(orig_etype, evalue, records)\n",
      "  File \"/Users/mindongjun/opt/anaconda3/envs/test2/lib/python3.7/site-packages/IPython/core/ultratb.py\", line 382, in find_recursion\n",
      "    return len(records), 0\n",
      "TypeError: object of type 'NoneType' has no len()\n",
      "\n",
      "During handling of the above exception, another exception occurred:\n",
      "\n",
      "Traceback (most recent call last):\n",
      "  File \"/Users/mindongjun/opt/anaconda3/envs/test2/lib/python3.7/site-packages/IPython/core/interactiveshell.py\", line 2077, in showtraceback\n",
      "    stb = value._render_traceback_()\n",
      "AttributeError: 'TypeError' object has no attribute '_render_traceback_'\n",
      "\n",
      "During handling of the above exception, another exception occurred:\n",
      "\n",
      "Traceback (most recent call last):\n",
      "  File \"/Users/mindongjun/opt/anaconda3/envs/test2/lib/python3.7/site-packages/IPython/core/ultratb.py\", line 1101, in get_records\n",
      "    return _fixed_getinnerframes(etb, number_of_lines_of_context, tb_offset)\n",
      "  File \"/Users/mindongjun/opt/anaconda3/envs/test2/lib/python3.7/site-packages/IPython/core/ultratb.py\", line 248, in wrapped\n",
      "    return f(*args, **kwargs)\n",
      "  File \"/Users/mindongjun/opt/anaconda3/envs/test2/lib/python3.7/site-packages/IPython/core/ultratb.py\", line 281, in _fixed_getinnerframes\n",
      "    records = fix_frame_records_filenames(inspect.getinnerframes(etb, context))\n",
      "  File \"/Users/mindongjun/opt/anaconda3/envs/test2/lib/python3.7/inspect.py\", line 1495, in getinnerframes\n",
      "    frameinfo = (tb.tb_frame,) + getframeinfo(tb, context)\n",
      "  File \"/Users/mindongjun/opt/anaconda3/envs/test2/lib/python3.7/inspect.py\", line 1453, in getframeinfo\n",
      "    filename = getsourcefile(frame) or getfile(frame)\n",
      "  File \"/Users/mindongjun/opt/anaconda3/envs/test2/lib/python3.7/inspect.py\", line 696, in getsourcefile\n",
      "    if getattr(getmodule(object, filename), '__loader__', None) is not None:\n",
      "  File \"/Users/mindongjun/opt/anaconda3/envs/test2/lib/python3.7/inspect.py\", line 733, in getmodule\n",
      "    if ismodule(module) and hasattr(module, '__file__'):\n",
      "  File \"/Users/mindongjun/opt/anaconda3/envs/test2/lib/python3.7/site-packages/tensorflow/__init__.py\", line 50, in __getattr__\n",
      "    module = self._load()\n",
      "  File \"/Users/mindongjun/opt/anaconda3/envs/test2/lib/python3.7/site-packages/tensorflow/__init__.py\", line 44, in _load\n",
      "    module = _importlib.import_module(self.__name__)\n",
      "  File \"/Users/mindongjun/opt/anaconda3/envs/test2/lib/python3.7/importlib/__init__.py\", line 127, in import_module\n",
      "    return _bootstrap._gcd_import(name[level:], package, level)\n",
      "  File \"<frozen importlib._bootstrap>\", line 1006, in _gcd_import\n",
      "  File \"<frozen importlib._bootstrap>\", line 983, in _find_and_load\n",
      "  File \"<frozen importlib._bootstrap>\", line 965, in _find_and_load_unlocked\n",
      "ModuleNotFoundError: No module named 'tensorflow_core.estimator'\n"
     ]
    }
   ],
   "source": [
    "# Lab 11 MNIST and Convolutional Neural Network\n",
    "import tensorflow as tf\n",
    "import random\n",
    "# import matplotlib.pyplot as plt\n",
    "\n",
    "from tensorflow.examples.tutorials.mnist import input_data\n",
    "\n",
    "tf.set_random_seed(777)  # reproducibility\n",
    "\n",
    "mnist = input_data.read_data_sets(\"MNIST_data/\", one_hot=True)\n",
    "# Check out https://www.tensorflow.org/get_started/mnist/beginners for\n",
    "# more information about the mnist dataset\n",
    "\n",
    "# hyper parameters\n",
    "learning_rate = 0.001\n",
    "training_epochs = 15\n",
    "batch_size = 100\n",
    "\n",
    "# input place holders\n",
    "X = tf.placeholder(tf.float32, [None, 784])\n",
    "X_img = tf.reshape(X, [-1, 28, 28, 1])   # img 28x28x1 (black/white)\n",
    "Y = tf.placeholder(tf.float32, [None, 10])\n",
    "\n",
    "# L1 ImgIn shape=(?, 28, 28, 1)\n",
    "W1 = tf.Variable(tf.random_normal([3, 3, 1, 32], stddev=0.01))\n",
    "#    Conv     -> (?, 28, 28, 32)\n",
    "#    Pool     -> (?, 14, 14, 32)\n",
    "L1 = tf.nn.conv2d(X_img, W1, strides=[1, 1, 1, 1], padding='SAME')\n",
    "L1 = tf.nn.relu(L1)\n",
    "L1 = tf.nn.max_pool(L1, ksize=[1, 2, 2, 1],\n",
    "                    strides=[1, 2, 2, 1], padding='SAME')\n",
    "'''\n",
    "Tensor(\"Conv2D:0\", shape=(?, 28, 28, 32), dtype=float32)\n",
    "Tensor(\"Relu:0\", shape=(?, 28, 28, 32), dtype=float32)\n",
    "Tensor(\"MaxPool:0\", shape=(?, 14, 14, 32), dtype=float32)\n",
    "'''\n",
    "\n",
    "# L2 ImgIn shape=(?, 14, 14, 32)\n",
    "W2 = tf.Variable(tf.random_normal([3, 3, 32, 64], stddev=0.01))\n",
    "#    Conv      ->(?, 14, 14, 64)\n",
    "#    Pool      ->(?, 7, 7, 64)\n",
    "L2 = tf.nn.conv2d(L1, W2, strides=[1, 1, 1, 1], padding='SAME')\n",
    "L2 = tf.nn.relu(L2)\n",
    "L2 = tf.nn.max_pool(L2, ksize=[1, 2, 2, 1],\n",
    "                    strides=[1, 2, 2, 1], padding='SAME')\n",
    "L2_flat = tf.reshape(L2, [-1, 7 * 7 * 64])\n",
    "'''\n",
    "Tensor(\"Conv2D_1:0\", shape=(?, 14, 14, 64), dtype=float32)\n",
    "Tensor(\"Relu_1:0\", shape=(?, 14, 14, 64), dtype=float32)\n",
    "Tensor(\"MaxPool_1:0\", shape=(?, 7, 7, 64), dtype=float32)\n",
    "Tensor(\"Reshape_1:0\", shape=(?, 3136), dtype=float32)\n",
    "'''\n",
    "\n",
    "# Final FC 7x7x64 inputs -> 10 outputs\n",
    "W3 = tf.get_variable(\"W3\", shape=[7 * 7 * 64, 10],\n",
    "                     initializer=tf.contrib.layers.xavier_initializer())\n",
    "b = tf.Variable(tf.random_normal([10]))\n",
    "logits = tf.matmul(L2_flat, W3) + b\n",
    "\n",
    "# define cost/loss & optimizer\n",
    "cost = tf.reduce_mean(tf.nn.softmax_cross_entropy_with_logits(\n",
    "    logits=logits, labels=Y))\n",
    "optimizer = tf.train.AdamOptimizer(learning_rate=learning_rate).minimize(cost)\n",
    "\n",
    "# initialize\n",
    "sess = tf.Session()\n",
    "sess.run(tf.global_variables_initializer())\n",
    "\n",
    "# train my model\n",
    "print('Learning started. It takes sometime.')\n",
    "for epoch in range(training_epochs):\n",
    "    avg_cost = 0\n",
    "    total_batch = int(mnist.train.num_examples / batch_size)\n",
    "\n",
    "    for i in range(total_batch):\n",
    "        batch_xs, batch_ys = mnist.train.next_batch(batch_size)\n",
    "        feed_dict = {X: batch_xs, Y: batch_ys}\n",
    "        c, _ = sess.run([cost, optimizer], feed_dict=feed_dict)\n",
    "        avg_cost += c / total_batch\n",
    "\n",
    "    print('Epoch:', '%04d' % (epoch + 1), 'cost =', '{:.9f}'.format(avg_cost))\n",
    "\n",
    "print('Learning Finished!')\n",
    "\n",
    "# Test model and check accuracy\n",
    "correct_prediction = tf.equal(tf.argmax(logits, 1), tf.argmax(Y, 1))\n",
    "accuracy = tf.reduce_mean(tf.cast(correct_prediction, tf.float32))\n",
    "print('Accuracy:', sess.run(accuracy, feed_dict={\n",
    "      X: mnist.test.images, Y: mnist.test.labels}))\n",
    "\n",
    "# Get one and predict\n",
    "r = random.randint(0, mnist.test.num_examples - 1)\n",
    "print(\"Label: \", sess.run(tf.argmax(mnist.test.labels[r:r + 1], 1)))\n",
    "print(\"Prediction: \", sess.run(\n",
    "    tf.argmax(logits, 1), feed_dict={X: mnist.test.images[r:r + 1]}))\n",
    "\n",
    "# plt.imshow(mnist.test.images[r:r + 1].\n",
    "#           reshape(28, 28), cmap='Greys', interpolation='nearest')\n",
    "# plt.show()\n",
    "\n",
    "'''\n",
    "Epoch: 0001 cost = 0.340291267\n",
    "Epoch: 0002 cost = 0.090731326\n",
    "Epoch: 0003 cost = 0.064477619\n",
    "Epoch: 0004 cost = 0.050683064\n",
    "Epoch: 0005 cost = 0.041864835\n",
    "Epoch: 0006 cost = 0.035760704\n",
    "Epoch: 0007 cost = 0.030572132\n",
    "Epoch: 0008 cost = 0.026207981\n",
    "Epoch: 0009 cost = 0.022622454\n",
    "Epoch: 0010 cost = 0.019055919\n",
    "Epoch: 0011 cost = 0.017758641\n",
    "Epoch: 0012 cost = 0.014156652\n",
    "Epoch: 0013 cost = 0.012397016\n",
    "Epoch: 0014 cost = 0.010693789\n",
    "Epoch: 0015 cost = 0.009469977\n",
    "Learning Finished!\n",
    "Accuracy: 0.9885\n",
    "'''"
   ]
  }
 ],
 "metadata": {
  "kernelspec": {
   "display_name": "Python 3.7.0 ('test2')",
   "language": "python",
   "name": "python3"
  },
  "language_info": {
   "codemirror_mode": {
    "name": "ipython",
    "version": 3
   },
   "file_extension": ".py",
   "mimetype": "text/x-python",
   "name": "python",
   "nbconvert_exporter": "python",
   "pygments_lexer": "ipython3",
   "version": "3.7.0"
  },
  "orig_nbformat": 4,
  "vscode": {
   "interpreter": {
    "hash": "3a129cd62a9a0696987b02b9aa02558856d3df1fbe04ae6225da87b58ee16246"
   }
  }
 },
 "nbformat": 4,
 "nbformat_minor": 2
}
